<mujoco model="cart_pendulum1">
    <worldbody>
        <body name="cart_1" pos="0 0 0.1">
            <joint name="slider_1" type="slide" axis="1 0 0" />
            <geom name="cart_geom_1" type="box" size="0.5 0.3 0.1" mass="1.0" />
            <body name="stand_1" pos="0 0.2 0.6">
                <geom name="stand_geom_1" type="box" size="0.05 0.05 0.6" mass="0" />
                <body name="arm1_1" pos="0 -0.2 0.6">
                    <joint name="hinge1_1" type="hinge" axis="0 1 0"/>
                    <geom name="arm1_geom_1" type="capsule" fromto="0 0 0 0 0 0.5" size="0.03" mass="0" />
                    <body name="mass1_1" pos="0 0 0.5">
                        <geom name="mass1_geom_1" type="sphere" size="0.07" mass="0.1" rgba="0.8 0.2 0.2 1"/>
                    </body>
                    <body name="arm2_1" pos="0 0 0.5">
                        <joint name="hinge2_1" type="hinge" axis="0 1 0"/>
                        <geom name="arm2_geom_1" type="capsule" fromto="0 0 0 0 0 0.5" size="0.03" mass="0" />
                        <body name="mass2_1" pos="0 0 0.5">
                            <geom name="mass2_geom_1" type="sphere" size="0.07" mass="0.1" rgba="0.2 0.2 0.8 1"/>
                        </body>
                    </body>
                </body>
            </body>
        </body>
    </worldbody>
</mujoco>